<?xml version="1.0"?>
<robot xmlns:xacro="http://www.ros.org/wiki/xacro" name="koala_robot">

  <link name="base_link"/>

  <link name="link_1">
    <visual>
      <geometry><cylinder length="0.1" radius="0.05"/></geometry>
    </visual>
  </link>

  <link name="link_2">
    <visual>
      <geometry><cylinder length="0.1" radius="0.05"/></geometry>
    </visual>
  </link>

  <joint name="joint_1" type="revolute">
    <parent link="base_link"/>
    <child link="link_1"/>
    <origin xyz="0 0 0.1" rpy="0 0 0"/>
    <axis xyz="0 0 1"/>
    <limit lower="-3.14" upper="3.14" effort="10" velocity="1.0"/>
  </joint>

  <joint name="joint_2" type="revolute">
    <parent link="link_1"/>
    <child link="link_2"/>
    <origin xyz="0 0 0.1" rpy="0 0 0"/>
    <axis xyz="0 0 1"/>
    <limit lower="-3.14" upper="3.14" effort="10" velocity="1.0"/>
  </joint>


  <ros2_control name="BearHardware" type="system">
    <hardware>
      <plugin>bear_hardware_interface/BearSystemHardware</plugin>
      <param name="port_name">/dev/ttyUSB0</param>
      <param name="baudrate">7500000</param>
      <param name="motor_ids">1,2</param>
    </hardware>

    <joint name="joint_1">
      <command_interface name="position"/>
      <state_interface name="position"/>
      <state_interface name="velocity"/>
    </joint>

    <joint name="joint_2">
      <command_interface name="position"/>
      <state_interface name="position"/>
      <state_interface name="velocity"/>
    </joint>
  </ros2_control>

</robot>